[2025-02-17T16:28:12.965+0000] {local_task_job_runner.py:123} INFO - ::group::Pre task execution logs
[2025-02-17T16:28:13.113+0000] {taskinstance.py:2614} INFO - Dependencies all met for dep_context=non-requeueable deps ti=<TaskInstance: tax_etl_pipeline.run_tax_etl manual__2025-02-17T16:28:06.258548+00:00 [queued]>
[2025-02-17T16:28:13.174+0000] {taskinstance.py:2614} INFO - Dependencies all met for dep_context=requeueable deps ti=<TaskInstance: tax_etl_pipeline.run_tax_etl manual__2025-02-17T16:28:06.258548+00:00 [queued]>
[2025-02-17T16:28:13.175+0000] {taskinstance.py:2867} INFO - Starting attempt 1 of 2
[2025-02-17T16:28:13.247+0000] {taskinstance.py:2890} INFO - Executing <Task(PythonOperator): run_tax_etl> on 2025-02-17 16:28:06.258548+00:00
[2025-02-17T16:28:13.452+0000] {standard_task_runner.py:104} INFO - Running: ['***', 'tasks', 'run', 'tax_etl_pipeline', 'run_tax_etl', 'manual__2025-02-17T16:28:06.258548+00:00', '--job-id', '3', '--raw', '--subdir', 'DAGS_FOLDER/tax_etl_dag.py', '--cfg-path', '/tmp/tmp9wzz25iy']
[2025-02-17T16:28:13.462+0000] {logging_mixin.py:190} WARNING - /home/***/.local/lib/python3.12/site-packages/***/task/task_runner/standard_task_runner.py:70 DeprecationWarning: This process (pid=184) is multi-threaded, use of fork() may lead to deadlocks in the child.
[2025-02-17T16:28:13.480+0000] {standard_task_runner.py:105} INFO - Job 3: Subtask run_tax_etl
[2025-02-17T16:28:13.484+0000] {standard_task_runner.py:72} INFO - Started process 187 to run task
[2025-02-17T16:28:16.776+0000] {task_command.py:467} INFO - Running <TaskInstance: tax_etl_pipeline.run_tax_etl manual__2025-02-17T16:28:06.258548+00:00 [running]> on host 341c015fbe61
[2025-02-17T16:28:18.520+0000] {taskinstance.py:3134} INFO - Exporting env vars: AIRFLOW_CTX_DAG_OWNER='***' AIRFLOW_CTX_DAG_ID='tax_etl_pipeline' AIRFLOW_CTX_TASK_ID='run_tax_etl' AIRFLOW_CTX_EXECUTION_DATE='2025-02-17T16:28:06.258548+00:00' AIRFLOW_CTX_TRY_NUMBER='1' AIRFLOW_CTX_DAG_RUN_ID='manual__2025-02-17T16:28:06.258548+00:00'
[2025-02-17T16:28:18.596+0000] {taskinstance.py:732} INFO - ::endgroup::
[2025-02-17T16:28:19.680+0000] {taskinstance.py:3313} ERROR - Task failed with exception
Traceback (most recent call last):
  File "/home/airflow/.local/lib/python3.12/site-packages/airflow/models/taskinstance.py", line 768, in _execute_task
    result = _execute_callable(context=context, **execute_callable_kwargs)
             ^^^^^^^^^^^^^^^^^^^^^^^^^^^^^^^^^^^^^^^^^^^^^^^^^^^^^^^^^^^^^
  File "/home/airflow/.local/lib/python3.12/site-packages/airflow/models/taskinstance.py", line 734, in _execute_callable
    return ExecutionCallableRunner(
           ^^^^^^^^^^^^^^^^^^^^^^^^
  File "/home/airflow/.local/lib/python3.12/site-packages/airflow/utils/operator_helpers.py", line 252, in run
    return self.func(*args, **kwargs)
           ^^^^^^^^^^^^^^^^^^^^^^^^^^
  File "/home/airflow/.local/lib/python3.12/site-packages/airflow/models/baseoperator.py", line 424, in wrapper
    return func(self, *args, **kwargs)
           ^^^^^^^^^^^^^^^^^^^^^^^^^^^
  File "/home/airflow/.local/lib/python3.12/site-packages/airflow/operators/python.py", line 238, in execute
    return_value = self.execute_callable()
                   ^^^^^^^^^^^^^^^^^^^^^^^
  File "/home/airflow/.local/lib/python3.12/site-packages/airflow/operators/python.py", line 256, in execute_callable
    return runner.run(*self.op_args, **self.op_kwargs)
           ^^^^^^^^^^^^^^^^^^^^^^^^^^^^^^^^^^^^^^^^^^^
  File "/home/airflow/.local/lib/python3.12/site-packages/airflow/utils/operator_helpers.py", line 252, in run
    return self.func(*args, **kwargs)
           ^^^^^^^^^^^^^^^^^^^^^^^^^^
  File "/opt/airflow/dags/tax_etl_dag.py", line 48, in run_etl
    raise Exception(f"Script failed with error: {result.stderr}")
Exception: Script failed with error: python: can't open file '/opt/***/etl/ETL_micro_batch/main.py': [Errno 2] No such file or directory

[2025-02-17T16:28:19.866+0000] {taskinstance.py:1226} INFO - Marking task as UP_FOR_RETRY. dag_id=tax_etl_pipeline, task_id=run_tax_etl, run_id=manual__2025-02-17T16:28:06.258548+00:00, execution_date=20250217T162806, start_date=20250217T162813, end_date=20250217T162819
[2025-02-17T16:28:19.974+0000] {taskinstance.py:341} INFO - ::group::Post task execution logs
[2025-02-17T16:28:19.982+0000] {standard_task_runner.py:124} ERROR - Failed to execute job 3 for task run_tax_etl (Script failed with error: python: can't open file '/opt/***/etl/ETL_micro_batch/main.py': [Errno 2] No such file or directory
; 187)
Traceback (most recent call last):
  File "/home/airflow/.local/lib/python3.12/site-packages/airflow/task/task_runner/standard_task_runner.py", line 117, in _start_by_fork
    ret = args.func(args, dag=self.dag)
          ^^^^^^^^^^^^^^^^^^^^^^^^^^^^^
  File "/home/airflow/.local/lib/python3.12/site-packages/airflow/cli/cli_config.py", line 49, in command
    return func(*args, **kwargs)
           ^^^^^^^^^^^^^^^^^^^^^
  File "/home/airflow/.local/lib/python3.12/site-packages/airflow/utils/cli.py", line 116, in wrapper
    return f(*args, **kwargs)
           ^^^^^^^^^^^^^^^^^^
  File "/home/airflow/.local/lib/python3.12/site-packages/airflow/cli/commands/task_command.py", line 483, in task_run
    task_return_code = _run_task_by_selected_method(args, _dag, ti)
                       ^^^^^^^^^^^^^^^^^^^^^^^^^^^^^^^^^^^^^^^^^^^^
  File "/home/airflow/.local/lib/python3.12/site-packages/airflow/cli/commands/task_command.py", line 256, in _run_task_by_selected_method
    return _run_raw_task(args, ti)
           ^^^^^^^^^^^^^^^^^^^^^^^
  File "/home/airflow/.local/lib/python3.12/site-packages/airflow/cli/commands/task_command.py", line 341, in _run_raw_task
    return ti._run_raw_task(
           ^^^^^^^^^^^^^^^^^
  File "/home/airflow/.local/lib/python3.12/site-packages/airflow/utils/session.py", line 97, in wrapper
    return func(*args, session=session, **kwargs)
           ^^^^^^^^^^^^^^^^^^^^^^^^^^^^^^^^^^^^^^
  File "/home/airflow/.local/lib/python3.12/site-packages/airflow/models/taskinstance.py", line 3006, in _run_raw_task
    return _run_raw_task(
           ^^^^^^^^^^^^^^
  File "/home/airflow/.local/lib/python3.12/site-packages/airflow/models/taskinstance.py", line 274, in _run_raw_task
    TaskInstance._execute_task_with_callbacks(
  File "/home/airflow/.local/lib/python3.12/site-packages/airflow/models/taskinstance.py", line 3161, in _execute_task_with_callbacks
    result = self._execute_task(context, task_orig)
             ^^^^^^^^^^^^^^^^^^^^^^^^^^^^^^^^^^^^^^
  File "/home/airflow/.local/lib/python3.12/site-packages/airflow/models/taskinstance.py", line 3185, in _execute_task
    return _execute_task(self, context, task_orig)
           ^^^^^^^^^^^^^^^^^^^^^^^^^^^^^^^^^^^^^^^
  File "/home/airflow/.local/lib/python3.12/site-packages/airflow/models/taskinstance.py", line 768, in _execute_task
    result = _execute_callable(context=context, **execute_callable_kwargs)
             ^^^^^^^^^^^^^^^^^^^^^^^^^^^^^^^^^^^^^^^^^^^^^^^^^^^^^^^^^^^^^
  File "/home/airflow/.local/lib/python3.12/site-packages/airflow/models/taskinstance.py", line 734, in _execute_callable
    return ExecutionCallableRunner(
           ^^^^^^^^^^^^^^^^^^^^^^^^
  File "/home/airflow/.local/lib/python3.12/site-packages/airflow/utils/operator_helpers.py", line 252, in run
    return self.func(*args, **kwargs)
           ^^^^^^^^^^^^^^^^^^^^^^^^^^
  File "/home/airflow/.local/lib/python3.12/site-packages/airflow/models/baseoperator.py", line 424, in wrapper
    return func(self, *args, **kwargs)
           ^^^^^^^^^^^^^^^^^^^^^^^^^^^
  File "/home/airflow/.local/lib/python3.12/site-packages/airflow/operators/python.py", line 238, in execute
    return_value = self.execute_callable()
                   ^^^^^^^^^^^^^^^^^^^^^^^
  File "/home/airflow/.local/lib/python3.12/site-packages/airflow/operators/python.py", line 256, in execute_callable
    return runner.run(*self.op_args, **self.op_kwargs)
           ^^^^^^^^^^^^^^^^^^^^^^^^^^^^^^^^^^^^^^^^^^^
  File "/home/airflow/.local/lib/python3.12/site-packages/airflow/utils/operator_helpers.py", line 252, in run
    return self.func(*args, **kwargs)
           ^^^^^^^^^^^^^^^^^^^^^^^^^^
  File "/opt/airflow/dags/tax_etl_dag.py", line 48, in run_etl
    raise Exception(f"Script failed with error: {result.stderr}")
Exception: Script failed with error: python: can't open file '/opt/***/etl/ETL_micro_batch/main.py': [Errno 2] No such file or directory

[2025-02-17T16:28:20.009+0000] {local_task_job_runner.py:266} INFO - Task exited with return code 1
[2025-02-17T16:28:20.128+0000] {taskinstance.py:3901} INFO - 0 downstream tasks scheduled from follow-on schedule check
[2025-02-17T16:28:20.149+0000] {local_task_job_runner.py:245} INFO - ::endgroup::
